<!--
Copyright (c) 2024  Carnegie Mellon University and Miraikan

Permission is hereby granted, free of charge, to any person obtaining a copy
of this software and associated documentation files (the "Software"), to deal
in the Software without restriction, including without limitation the rights
to use, copy, modify, merge, publish, distribute, sublicense, and/or sell
copies of the Software, and to permit persons to whom the Software is
furnished to do so, subject to the following conditions:

The above copyright notice and this permission notice shall be included in
all copies or substantial portions of the Software.

THE SOFTWARE IS PROVIDED "AS IS", WITHOUT WARRANTY OF ANY KIND, EXPRESS OR
IMPLIED, INCLUDING BUT NOT LIMITED TO THE WARRANTIES OF MERCHANTABILITY,
FITNESS FOR A PARTICULAR PURPOSE AND NONINFRINGEMENT. IN NO EVENT SHALL THE
AUTHORS OR COPYRIGHT HOLDERS BE LIABLE FOR ANY CLAIM, DAMAGES OR OTHER
LIABILITY, WHETHER IN AN ACTION OF CONTRACT, TORT OR OTHERWISE, ARISING FROM,
OUT OF OR IN CONNECTION WITH THE SOFTWARE OR THE USE OR OTHER DEALINGS IN
THE SOFTWARE.
-->

<robot name="cabot_description"
       xmlns:xacro="http://ros.org/wiki/xacro">
  <xacro:property name="M_PI" value="3.1415926535897931" />

  <xacro:macro name="cabot" params="offset:=^ sim:=^|true">
    <xacro:property name="BODY_X" value="0.36" /> <!-- measured (399.41mm) -->
    <xacro:property name="BODY_Y" value="0.24" /> <!-- measured -->
    <xacro:property name="BODY_Z" value="0.48" /> <!-- measured -->
    <xacro:property name="WHEEL_RADIUS" value="0.087" /> <!-- the same with cabot3-k1 -->
    <xacro:property name="CLEARANCE" value="0.0798" /> <!-- measured -->
    <xacro:property name="WHEEL_WIDTH" value="0.051" /> <!-- the same with cabot3-k1 -->
    <xacro:property name="WHEEL_BIAS" value="0.139" /> <!-- measured -->
    <xacro:property name="FREEWHEEL_BIAS" value="0.1474" /> <!-- measured -->
    <xacro:property name="LIDAR_X" value="0.1" /> 
    <xacro:property name="bluegray_r" value="${103/255}" />
    <xacro:property name="bluegray_g" value="${134/255}" />
    <xacro:property name="bluegray_b" value="${150/255}" />

    <xacro:if value="${sim}">
      <gazebo>
        <plugin name="differential_drive_controller" filename="libgazebo_ros_diff_drive.so">
          <max_wheel_acceleration>1.0</max_wheel_acceleration>
          <max_wheel_torque>10.0</max_wheel_torque>
          <left_joint>awl_joint</left_joint>
          <right_joint>awr_joint</right_joint>
          <wheel_separation>${WHEEL_BIAS+WHEEL_WIDTH}</wheel_separation>
          <wheel_diameter>${WHEEL_RADIUS*2}</wheel_diameter>
          <update_rate>100.0</update_rate>
          <odometry_frame>odom</odometry_frame>
          <robot_base_frame>base_footprint</robot_base_frame>
          <odometry_source>0</odometry_source>
          <publish_odom>true</publish_odom>
          <publish_odom_tf>false</publish_odom_tf>
          <publish_wheel_tf>false</publish_wheel_tf>
          <ros>
            <argument>--ros-args</argument>
            <argument>-r</argument>
            <argument>/odom:=/cabot/odom_raw</argument>
            <argument>-r</argument>
            <argument>/cmd_vel:=/cabot/cmd_vel</argument>
          </ros>
        </plugin>
        <plugin name="gazebo_ros_joint_state_publisher" filename="libgazebo_ros_joint_state_publisher.so">
          <update_rate>10</update_rate>
          <joint_name>awl_joint</joint_name>
          <joint_name>awr_joint</joint_name>
        </plugin>
      </gazebo>

      <xacro:macro name="gazebo_wheel" params="reference">
        <gazebo reference="${reference}">
          <mu1>1.0</mu1>
          <mu2>1.0</mu2>
          <kp>100000.0</kp>
          <kd>1.0</kd>
          <minDepth>0.001</minDepth>
          <maxVel>100.0</maxVel>
          <soft_cfm>0.0</soft_cfm>
          <soft_erp>0.2</soft_erp>
        </gazebo>
      </xacro:macro>

      <xacro:macro name="gazebo_free_wheel" params="reference">
        <gazebo reference="${reference}">
          <material>Gazebo/Black</material>
          <mu1>0.01</mu1>
          <mu2>0.01</mu2>
          <kp>100000.0</kp>
          <kd>1.0</kd>
          <minDepth>0.001</minDepth>
          <maxVel>100.0</maxVel>
          <soft_cfm>0.0</soft_cfm>
          <soft_erp>0.2</soft_erp>
        </gazebo>
      </xacro:macro>

      <xacro:macro name="gazebo_color" params="reference color">
        <gazebo reference="${reference}">
          <material>${color}</material>
        </gazebo>
      </xacro:macro>

      <xacro:gazebo_wheel reference="awl_link" />
      <xacro:gazebo_wheel reference="awr_link" />
      <xacro:gazebo_free_wheel reference="vc1_link" />
      <xacro:gazebo_free_wheel reference="vc2_link" />
      <gazebo reference="base_link">
        <visual>
          <material>
            <ambient>${bluegray_r} ${bluegray_g} ${bluegray_b} 1.0</ambient>
            <diffuse>${bluegray_r} ${bluegray_g} ${bluegray_b} 1.0</diffuse>
            <specular>${bluegray_r} ${bluegray_g} ${bluegray_b}  1.0</specular>
            <emissive>0.0 0.0 0.0 0.0</emissive>
          </material>
        </visual>
      </gazebo>
      <xacro:gazebo_color reference="awl_link" color="Gazebo/DarkGrey" />
      <xacro:gazebo_color reference="awr_link" color="Gazebo/DarkGrey" />
      <xacro:gazebo_color reference="caster2_link" color="Gazebo/DarkGrey" />
      <xacro:gazebo_color reference="caster4_link" color="Gazebo/DarkGrey" />
      <xacro:gazebo_color reference="handle_link" color="Gazebo/DarkGrey" />
      <xacro:gazebo_color reference="grip_link" color="Gazebo/Silver" />
    </xacro:if>


    <xacro:macro name="bluegray_material">
      <material name="bluegray">
        <color rgba="${bluegray_r} ${bluegray_g} ${bluegray_b}  1.0" />
      </material>
    </xacro:macro>
    <xacro:macro name="alminium_material">
      <material name="alminium">
        <color rgba="0.9576 0.9594 0.9572 1" />
      </material>
    </xacro:macro>
    <xacro:macro name="black_material">
      <material name="black">
        <color rgba="0.2 0.2 0.2 1" />
      </material>
    </xacro:macro>
    <xacro:macro name="gray_material">
      <material name="gray">
        <color rgba="0.7 0.7 0.7 1" />
      </material>
    </xacro:macro>
    <xacro:macro name="white_material">
      <material name="white">
        <color rgba="1.0 1.0 1.0 1" />
      </material>
    </xacro:macro>

    <link name="base_footprint">
      <inertial>
        <origin xyz="0 0 0" rpy="0 0 0" />
        <mass value="0.001" />
        <inertia ixx="0" ixy="0" ixz="0" iyy="0" iyz="0" izz="0" />
      </inertial>
    </link>
    <link name="base_control_shift" />
    <link name="imu_frame" />

    <joint name="base_joint" type="prismatic">
      <axis xyz="0 1 0" />
      <limit lower="0" upper="0" effort="10" velocity="1" />
      <origin xyz="0 0 0" rpy="0 0 0" />
      <parent link="base_footprint" />
      <child link="base_control_shift" />
    </joint>

    <joint name="control_center_joint" type="fixed">
      <origin xyz="0.10 0 ${WHEEL_RADIUS}" rpy="0 0 0" />
      <parent link="base_control_shift" />
      <child link="base_link" />
    </joint>

    <joint name="imu_joint" type="fixed">
      <origin xyz="0.21 0 0" rpy="0 0 0" /> <!--real imu xyz "0.128762 -0.01689 0.09487  -->
      <parent link="base_control_shift" />
      <child link="imu_frame" />
    </joint>

    <link name="base_link">
      <inertial>
        <origin xyz="0 0 0.1" rpy="0 0 0" />
        <mass value="22" />
        <inertia ixx="0.528" ixy="0" ixz="0" iyy="0.66" iyz="0" izz="0.3432" />
      </inertial>
      <!-- main body -->
      <visual>
        <origin xyz="0 0 ${CLEARANCE - WHEEL_RADIUS}" rpy="0 0 0" />
        <geometry>
          <mesh scale="0.0001 0.0001 0.0001" filename="package://cabot_description/meshes/cabot3-k4_body.stl" /> 
        </geometry>
        <xacro:bluegray_material />
      </visual>
      <collision>
        <origin xyz="0 0 ${BODY_Z/2 + CLEARANCE - WHEEL_RADIUS}" rpy="0 0 0" /> 
        <geometry>
          <box size="${BODY_X} ${BODY_Y} ${BODY_Z}" />
        </geometry>
      </collision>
    </link>

    <xacro:macro name="wheel" params="name xyz rpy">
      <link name="${name}_link">
        <inertial>
          <origin xyz="0 0 0" rpy="0 0 0" />
          <mass value="2.2" />
          <inertia ixx="0.004642" ixy="0" ixz="0" iyy="0.004642" iyz="0" izz="0.00833" />
        </inertial>
        <visual>
          <origin xyz="0 0 0" rpy="0 0 0" />
          <geometry>
            <cylinder length="${WHEEL_WIDTH}" radius="${WHEEL_RADIUS}" />
          </geometry>
          <xacro:black_material />
        </visual>
        <collision>
          <origin xyz="0 0 0" rpy="0 0 0" />
          <geometry>
            <cylinder length="${WHEEL_WIDTH}" radius="${WHEEL_RADIUS}" />
          </geometry>
        </collision>
      </link>
      <joint name="${name}_joint" type="continuous">
        <origin xyz="${xyz}" rpy="${rpy}" />
        <parent link="base_control_shift" />
        <child link="${name}_link" />
        <axis xyz="0 0 1" />
        <limit effort="0" velocity="1.0" />
      </joint>														
    </xacro:macro>

    <xacro:wheel name="awl" xyz="0.01 ${WHEEL_BIAS/2} ${WHEEL_RADIUS}" rpy="${-M_PI/2} 0 0" />
    <xacro:wheel name="awr" xyz="0.01 ${-WHEEL_BIAS/2} ${WHEEL_RADIUS}" rpy="${-M_PI/2} 0 0" />

    <xacro:macro name="free_wheel" params="name xyz">
      <link name="${name}_link">
        <inertial>
          <origin xyz="0 0 0" rpy="0 0 0" />
          <mass value="0.0" />
          <inertia ixx="0.0" ixy="0.0" ixz="0.0" iyy="0.0" iyz="0.0" izz="0.0" />
        </inertial>
        <visual>
          <origin xyz="0 0 0" rpy="0 0 0" />
          <geometry>
            <mesh filename="package://cabot_description/meshes/cabot3-k4_${name}_link.stl" />
          </geometry>
          <xacro:black_material />
        </visual>
      </link>
      <joint name="${name}_joint" type="fixed">
        <origin xyz="${xyz}" rpy="0 ${-M_PI/2} ${-M_PI/2}" />
        <parent link="base_link" />
        <child link="${name}_link" />
        <axis xyz="1 0 0" />
      </joint>
    </xacro:macro>

    <xacro:free_wheel name="caster2" xyz="${BODY_X/2 - 0.014} ${FREEWHEEL_BIAS/2} 0.003" />
    <xacro:free_wheel name="caster4" xyz="${BODY_X/2 - 0.014} ${-FREEWHEEL_BIAS/2} 0.003" />

    <xacro:macro name="virtual_caster" params="name xyz">
      <link name="${name}_link">
        <inertial>
          <origin xyz="0 0 0" rpy="0 0 0" />
          <mass value="0.2" />
          <inertia ixx="0.000162" ixy="0.0" ixz="0.0" iyy="0.000162" iyz="0.0" izz="0.000162" />
        </inertial>
        <!-- # debug
             <visual>
             <origin xyz="0 0 0" rpy="0 0 0" />
             <geometry>
             <sphere radius="0.045" />
             </geometry>
             <material name="">
             <color rgba="0.79216 0.81961 0.93333 1" />
             </material>
             </visual>
        -->
        <collision>
          <origin xyz="0 0 0" rpy="0 0 0" />
          <geometry>
            <sphere radius="${WHEEL_RADIUS}" />
          </geometry>
        </collision>
      </link>
      <joint name="${name}_joint" type="fixed">
        <origin xyz="${xyz}" rpy="0 0 0" />
        <parent link="base_link" />
        <child link="${name}_link" />
        <axis xyz="1 0 0" />
      </joint>
    </xacro:macro>

    <xacro:virtual_caster name="vc1" xyz="${BODY_X/2 - WHEEL_RADIUS} 0 0" />

    <link name="handle_link">
      <inertial>
        <origin xyz="-4.3092E-17 0.26035 0.01" rpy="0 0 0" />
        <mass value="0.4228" />
        <inertia ixx="0.0091197" ixy="2.2522E-18" ixz="4.8405E-20" iyy="0.0016715" iyz="1.0605E-19" izz="0.010763" />
      </inertial>
      <visual>
        <origin xyz="0 0 0" rpy="0 0 0" />
        <geometry>
          <mesh scale="0.01 0.01 0.01" filename="package://cabot_description/meshes/cabot3-k4_handle.stl" />
        </geometry>
        <xacro:black_material />
      </visual>
      <collision>
        <origin xyz="0 0 0" rpy="0 0 0" />
        <geometry>
          <mesh scale="0.01 0.01 0.01" filename="package://cabot_description/meshes/cabot3-k4_handle.stl" />
        </geometry>
      </collision>
    </link>
    <link name="grip_link">
      <inertial>
        <origin xyz="-4.3092E-17 0.26035 0.01" rpy="${M_PI/2} 0 0" />
        <mass value="0.1228" />
        <inertia ixx="0.0091197" ixy="2.2522E-18" ixz="4.8405E-20" iyy="0.0016715" iyz="1.0605E-19" izz="0.010763" />
      </inertial>
      <visual>
        <origin xyz="0 0 0" rpy="0 0 0" />
        <geometry>
          <mesh scale="0.1 0.1 0.1" filename="package://cabot_description/meshes/cabot3-k4_grip.stl" />
        </geometry>
        <xacro:alminium_material />
      </visual>
    </link>
    <joint name="handle_joint" type="fixed">
      <origin xyz="-0.04 0.013 0.281" rpy="${M_PI/2} 0 0" />
      <parent link="base_link" />
      <child link="handle_link" />
      <axis xyz="0 0 0" />
    </joint>
    <joint name="grip_joint" type="fixed">
      <origin xyz="-0.04 0 ${0.281+0.627} " rpy="${M_PI/2} 0 0" />
      <parent link="base_link" />
      <child link="grip_link" />
      <axis xyz="0 0 0" />
    </joint>
    
    <link name="lidarcover_link">
      <inertial>
        <origin xyz="0 0 0" rpy="0 0 0" />
        <mass value="0.0" />
        <inertia ixx="0.0" ixy="0.0" ixz="0.0" iyy="0.0" iyz="0.0" izz="0.0" />
      </inertial>
      <visual>
        <origin xyz="0 0 0" rpy="0 0 0" />
        <geometry>
          <mesh scale="0.1 0.1 0.1" filename="package://cabot_description/meshes/cabot3-k4_lidar_pole.stl" />
        </geometry>
        <xacro:white_material />
      </visual>
    </link>
    <joint name="lidarcover_joint" type="fixed">
      <origin xyz="-0.016 0 ${0.48 - 0.0155}" rpy="0 0 0" />
      <parent link="base_link" />
      <child link="lidarcover_link" />
      <axis xyz="0 0 0" />
    </joint>
    
    <link name="cover_left_link">
      <inertial>
        <origin xyz="0 0 0" rpy="0 0 0" />
        <mass value="0.0" />
        <inertia ixx="0.0" ixy="0.0" ixz="0.0" iyy="0.0" iyz="0.0" izz="0.0" />
      </inertial>
      <visual>
        <origin xyz="0 0 0" rpy="0 0 0" />
        <geometry>
          <mesh scale="0.001 0.001 0.001" filename="package://cabot_description/meshes/cabot3-k4_leftpanel.stl" />
        </geometry>
        <xacro:white_material />
      </visual>
    </link>
    <joint name="cover_left_joint" type="fixed">
      <origin xyz="0 -0.101 ${CLEARANCE - WHEEL_RADIUS} " rpy="0 0 0" />
      <parent link="base_link" />
      <child link="cover_left_link" />
      <axis xyz="0 0 0" />
    </joint>
    
    <link name="cover_right_link">
      <inertial>
        <origin xyz="0 0 0" rpy="0 0 0" />
        <mass value="0.0" />
        <inertia ixx="0.0" ixy="0.0" ixz="0.0" iyy="0.0" iyz="0.0" izz="0.0" />
      </inertial>
      <visual>
        <origin xyz="0 0 0" rpy="0 0 0" />
        <geometry>
          <mesh scale="0.001 0.001 0.001" filename="package://cabot_description/meshes/cabot3-k4_rightpanel.stl" />
        </geometry>
        <xacro:white_material />
      </visual>
    </link>
    <joint name="cover_right_joint" type="fixed">
      <origin xyz="0 0.101 ${CLEARANCE - WHEEL_RADIUS} " rpy="0 0 0" />
      <parent link="base_link" />
      <child link="cover_right_link" />
      <axis xyz="0 0 0" />
    </joint>
  </xacro:macro>
</robot>
